Workbook
Name _Ref166757325: 'Consumo Eléctrico'!$AJ$163
Name _Ref166765020: 'Consumo Eléctrico'!$G$75
Name POWER_USER_EXCEL_CHART_0C3E92C7_7122_4BCD_BE41_CA79122D9A12: 'Balance Energético'!$H$4:$S$6
Name POWER_USER_EXCEL_CHART_32786930_8C68_4D96_B573_65ADC75C9CB6: 'Balance Energético'!$H$4:$S$6
Name POWER_USER_EXCEL_CHART_8CFC428E_CDBF_457F_A59C_577F12BD97F4: 'Balance Térmico'!$E$73:$H$76
Name POWER_USER_EXCEL_CHART_F369CD19_B1EC_48BB_85C9_292C8ACCD36A: 'Balance Energético'!$H$4:$S$6

Sheet Consumo Eléctrico
D2: Histórico de Factura Eléctrica 2022-2023
F3: Medio | G3: Alto | H3: Económico
B5: PERÍODO FACTURA | F5: CONSUMO [kWh]
B6: Mes | C6: Inicio | D6: Término | E6: Días | F6: Horario Llano (08:00 - 18:00) | G6: Horario Punta (18:00 - 22:00) | H6: Horario Valle (22:00 - 08:00) | I6: Total Consumo [kWh]
J7: [kWh] *10³
B8: 44562 | C8: 44564 | D8: 44595 | E8: =D8-C8 -> 31 | F8: 4980.29 | G8: 1781.62 | H8: 1912.92 | I8: =SUM(F8:H8) -> 8674.83 | J8: =I8/1000 -> 8.67483
B9: 44593 | C9: =D8 -> 44595 | D9: 44625 | E9: =D9-C9 -> 30 | F9: 6850.63 | G9: 1401.2 | H9: 1641.29 | I9: =SUM(F9:H9) -> 9893.12 | J9: =I9/1000 -> 9.89312 | AR9: 4980.29 | AS9: 1781.62 | AT9: 1912.92
B10: 44621 | C10: =D9 -> 44625 | D10: 44655 | E10: =D10-C10 -> 30 | F10: 6449.2 | G10: 1485.63 | H10: 1754.42 | I10: =SUM(F10:H10) -> 9689.25 | J10: =I10/1000 -> 9.68925 | AR10: 6850.63 | AS10: 1401.2 | AT10: 1641.29
B11: 44652 | C11: =D10 -> 44655 | D11: 44686 | E11: =D11-C11 -> 31 | F11: 6612.52 | G11: 1598.12 | H11: 1612.92 | I11: =SUM(F11:H11) -> 9823.56 | J11: =I11/1000 -> 9.82356 | AR11: 6449.2 | AS11: 1485.63 | AT11: 1754.42
B12: 44682 | C12: =D11 -> 44686 | D12: 44716 | E12: =D12-C12 -> 30 | F12: 7284.73 | G12: 1650.53 | H12: 1568.63 | I12: =SUM(F12:H12) -> 10503.89 | J12: =I12/1000 -> 10.50389 | AR12: 6612.52 | AS12: 1598.12 | AT12: 1612.92
B13: 44713 | C13: =D12 -> 44716 | D13: 44747 | E13: =D13-C13 -> 31 | F13: 7217.46 | G13: 1246.34 | H13: 1467.53 | I13: =SUM(F13:H13) -> 9931.33 | J13: =I13/1000 -> 9.93133 | AR13: 7284.73 | AS13: 1650.53 | AT13: 1568.63
B14: 44743 | C14: =D13 -> 44747 | D14: 44777 | E14: =D14-C14 -> 30 | F14: 6847.8 | G14: 1287.75 | H14: 1533.18 | I14: =SUM(F14:H14) -> 9668.73 | J14: =I14/1000 -> 9.66873 | AR14: 7217.46 | AS14: 1246.34 | AT14: 1467.53
B15: 44774 | C15: =D14 -> 44777 | D15: 44807 | E15: =D15-C15 -> 30 | F15: 6895.23 | G15: 1189.23 | H15: 1413.67 | I15: =SUM(F15:H15) -> 9498.13 | J15: =I15/1000 -> 9.49813 | AR15: 6847.8 | AS15: 1287.75 | AT15: 1533.18
B16: 44805 | C16: =D15 -> 44807 | D16: 44837 | E16: =D16-C16 -> 30 | F16: 6853.88 | G16: 1096.88 | H16: 1334.23 | I16: =SUM(F16:H16) -> 9284.99 | J16: =I16/1000 -> 9.28499 | AR16: 6895.23 | AS16: 1189.23 | AT16: 1413.67
B17: 44835 | C17: =D16 -> 44837 | D17: 44868 | E17: =D17-C17 -> 31 | F17: 6495.31 | G17: 1172.61 | H17: 1377.64 | I17: =SUM(F17:H17) -> 9045.56 | J17: =I17/1000 -> 9.04556 | AR17: 6853.88 | AS17: 1096.88 | AT17: 1334.23
B18: 44866 | C18: =D17 -> 44868 | D18: 44899 | E18: =D18-C18 -> 31 | F18: 6921.53 | G18: 1262.5 | H18: 1492.78 | I18: =SUM(F18:H18) -> 9676.81 | J18: =I18/1000 -> 9.67681 | AR18: 6495.31 | AS18: 1172.61 | AT18: 1377.64
B19: 44896 | C19: =D18 -> 44899 | D19: 44929 | E19: =D19-C19 -> 30 | F19: 6019.6 | G19: 1188.77 | H19: 1369.56 | I19: =SUM(F19:H19) -> 8577.93 | J19: =I19/1000 -> 8.57793 | AR19: 6921.53 | AS19: 1262.5 | AT19: 1492.78
B20: 44927 | C20: =D19 -> 44929 | D20: 44960 | E20: =D20-C20 -> 31 | F20: 5203.63 | G20: 1498.52 | H20: 1772.85 | I20: =SUM(F20:H20) -> 8475 | J20: =I20/1000 -> 8.475 | AR20: 6019.6 | AS20: 1188.77 | AT20: 1369.56
... B31: 45261 | C31: =D30 -> 45263 | D31: 45294 | E31: =D31-C31 -> 31 | F31: 5795.3 | G31: 1251.45 | H31: 1421.5 | I31: =SUM(F31:H31) -> 8468.25 | J31: =I31/1000 -> 8.46825 | AR31: 7195.65 | AS31: 1312.5 | AT31: 1551.9
B32: Media (mes) 2022 | F32: =AVERAGE(F8:F19) -> 6619.015 | G32: =AVERAGE(G8:G19) -> 1363.4317 | H32: =AVERAGE(H8:H19) -> 1539.8975 | I32: =AVERAGE(I8:I19) -> 9522.3442 | J32: =I32/1000 -> 9.5223442 | AR32: 5795.3 | AS32: 1251.45 | AT32: 1421.5
B33: Total (anual) 2022 | F33: =SUM(F8:F19) -> 79428.18 | G33: =SUM(G8:G19) -> 16361.18 | H33: =SUM(H8:H19) -> 18478.77 | I33: =SUM(I8:I19) -> 114268.13 | J33: =I33/1000 -> 114.26813
B34: Media (mes) 2023 | F34: =AVERAGE(F20:F31) -> 6633.5175 | G34: =AVERAGE(G20:G31) -> 1291.82 | H34: =AVERAGE(H20:H31) -> 1496.7833 | I34: =AVERAGE(I20:I31) -> 9422.1208 | J34: =I34/1000 -> 9.4221208
B35: Total (anual) 2023 | F35: =SUM(F20:F31) -> 79602.21 | G35: =SUM(G20:G31) -> 15501.84 | H35: =SUM(H20:H31) -> 17961.4 | I35: =SUM(I20:I31) -> 113065.45 | J35: =I35/1000 -> 113.06545
I36: =I33+I35 -> 227333.58
E38: Horas x día | F38: 10 | G38: 4 | H38: 10
J39: [kWh] *10³
G40: Media mensual período 2022--2023 | J40: =AVERAGE(J8:J31) -> 9.4722325
G41: Media anaull período 2022--2023 | J41: =AVERAGE(J33,J35) -> 113.66679
H65: http://guiaiso50001.cl/guia/wp-content/uploads/2017/05/herramientas-para-la-planeacion-energetica-P-2-AP-1.pdf
B66: Línea de Base Energética - LBE PGF
J67: Protocolos de IPMVP | P67: Datos Planta Oil Malal San Antonio
B69: 1) Definición del período base | P69: 1) Definición del período base | X69: 6) Verificación de R² y filtrado de datos
X70: Z es el valor que da el ancho de la franja de flitrado
B71: 2) Definición de la muestra de datos mínima | P71: 2) Definición de la muestra de datos mínima | X71: Generalmente se comienza por el valor 4 y puede irse bajando hasta lograr el ancho de filtrado deseado
Y72: P | Z72: E
E73: Mes | F73: Consumo [kWh/mes] | G73: ='Indicadores Energéticos'!D4 -> Emulsión Asfáltica [m³/mes] | H73: DIF Consumo - Promedio | I73: Cuadrado de las diferencias | P73: Mes | Q73: Consumo [kWh/mes] | R73: ='Indicadores Energéticos'!D4 -> Emulsión Asfáltica [m³/mes] | S73: DIF Consumo - Promedio | T73: Cuadrado de las diferencias | X73: Mes | Y73: Producción [m³/mes] | Z73: Consumo [kWh/mes] | AA73: Consumo [MWh/mes] | AB73: E*E | AC73: E*P | AD73: Emodelo | AE73: Emod+Z*Sxy | AF73: Emod-Z*Sxy
E74: =B8 -> 44562 | F74: =I8 -> 8674.83 | G74: ='Indicadores Energéticos'!D8 -> 72.34458 | H74: =F74-$F$99 -> -797.4025 | I74: =H74^2 -> 635850.75 | P74: =B8 -> 44562 | Q74: =I8 -> 8674.83 | R74: ='Indicadores Energéticos'!D8 -> 72.34458 | S74: =Q74-$Q$98 -> -797.4025 | T74: =S74^2 -> 635850.75 | X74: =P74 -> 44562 | Y74: =R74 -> 72.34458 | Z74: =Q74 -> 8674.83 | AA74: =Z74/1000 -> 8.67483 | AB74: =Z74*Z74 -> 75252676 | AC74: =Z74*Y74 -> 627576.93 | AD74: =($AI$75*Y74)+$AI$77 -> 8810.6352 | AE74: =AD74+($AI$78*$Z$100) -> 9573.8949 | AF74: =AD74-($AI$78*$Z$100) -> 8047.3755 | AH74: Datos para cálculos
E75: =B9 -> 44593 | F75: =I9 -> 9893.12 | G75: ='Indicadores Energéticos'!D9 -> 99.4455 | H75: =F75-$F$99 -> 420.8875 | I75: =H75^2 -> 177146.29 | P75: =B9 -> 44593 | Q75: =I9 -> 9893.12 | R75: ='Indicadores Energéticos'!D9 -> 99.4455 | S75: =Q75-$Q$98 -> 420.8875 | T75: =S75^2 -> 177146.29 | X75: =P75 -> 44593 | Y75: =R75 -> 99.4455 | Z75: =Q75 -> 9893.12 | AA75: =Z75/1000 -> 9.89312 | AB75: =Z75*Z75 -> 97873823 | AC75: =Z75*Y75 -> 983826.26 | AD75: =($AI$75*Y75)+$AI$77 -> 9058.8477 | AE75: =AD75+($AI$78*$Z$100) -> 9822.1075 | AF75: =AD75-($AI$78*$Z$100) -> 8295.588 | AH75: Pendiente | AI75: =SLOPE(Z74:Z97,Y74:Y97) -> 9.1588228 | AJ75: m
E76: =B10 -> 44621 | F76: =I10 -> 9689.25 | G76: ='Indicadores Energéticos'!D10 -> 104.69536 | H76: =F76-$F$99 -> 217.0175 | I76: =H76^2 -> 47096.595 | P76: =B10 -> 44621 | Q76: =I10 -> 9689.25 | R76: ='Indicadores Energéticos'!D10 -> 104.69536 | S76: =Q76-$Q$98 -> 217.0175 | T76: =S76^2 -> 47096.595 | X76: =P76 -> 44621 | Y76: =R76 -> 104.69536 | Z76: =Q76 -> 9689.25 | AA76: =Z76/1000 -> 9.68925 | AB76: =Z76*Z76 -> 93881566 | AC76: =Z76*Y76 -> 1014419.5 | AD76: =($AI$75*Y76)+$AI$77 -> 9106.9303 | AE76: =AD76+($AI$78*$Z$100) -> 9870.19 | AF76: =AD76-($AI$78*$Z$100) -> 8343.6706 | AH76: Variable independiente | AJ76: P
E77: =B11 -> 44652 | F77: =I11 -> 9823.56 | G77: ='Indicadores Energéticos'!D11 -> 198.85866 | H77: =F77-$F$99 -> 351.3275 | I77: =H77^2 -> 123431.01 | P77: =B11 -> 44652 | Q77: =I11 -> 9823.56 | R77: ='Indicadores Energéticos'!D11 -> 198.85866 | S77: =Q77-$Q$98 -> 351.3275 | T77: =S77^2 -> 123431.01 | X77: =P77 -> 44652 | Y77: =R77 -> 198.85866 | Z77: =Q77 -> 9823.56 | AA77: =Z77/1000 -> 9.82356 | AB77: =Z77*Z77 -> 96502331 | AC77: =Z77*Y77 -> 1953500 | AD77: =($AI$75*Y77)+$AI$77 -> 9969.3553 | AE77: =AD77+($AI$78*$Z$100) -> 10732.615 | AF77: =AD77-($AI$78*$Z$100) -> 9206.0956 | AH77: Intercepto | AI77: =INTERCEPT(Z74:Z97,Y74:Y97) -> 8148.044 | AJ77: E₀
...

Sheet Consumo Térmico de la empresa
B2: media | C2: parafina | D2: 889
B3: top | C3: kerosene | D3: =D4/20 -> 1091
C4: 20 litros | D4: =21820 -> 21820
B5: 3.78541 | C5: galon $ | D5: =B5*D3 -> 4129.8823 | J5: Conversterin
C6: 1 dollar | D6: 966.19 | J6: https://es.converterin.com/economia-de-combustible/us-galones-de-gasoil-to-joule.html | R6: Factor de conversión de GJ a kW
C7: galon USD | D7: =D5/D6 -> 4.2743998 | L7: US galon de kerosene | N7: Joule | O7: Giga Joule | R7: https://es.converterin.com/economia-de-combustible/gigajoule-to-us-galones-de-kerosene.html
C8: galones x día | D8: =B5*3 -> 11.35623 | L8: 1 | N8: 140500000 | O8: =N8/1000000000 -> 0.1405 | R8: =277.77777778 -> 277.77778
N9: =142200000 -> 142200000 | O9: =N9/1000000000 -> 0.1422 | P9: Oficial
B10: CONSUMO [Kerosene] | N10: 130001500 | O10: =N10/1000000000 -> 0.1300015
N11: 140900000
B12: Datos de consumo de combustible 2022 | F12: Costo energía térmica | G12: =G13*G14*O8 -> 4119.7641 | N12: 140500000
F13: Galones | G13: 7.1 | N13: 146520000 | O13: =N13/1000000000 -> 0.14652
C14: Kerosene [gal] | D14: Kerosene [US$] | F14: Valor Galón | G14: =D5 -> 4129.8823
B15: Media Consumo mes | C15: =C37 -> 287.09912 | D15: 0
B16: Media Consumo anual | C16: =C15*12 -> 3445.1894 | D16: 0 | F16: Conversión
B17: Media Costo mes | C17: 0 | D17: =C15*D19 -> 1227.1764 | F17: Galón | G17: [GJ]
B18: Media Costo anual | C18: 0 | D18: =D17*12 -> 14726.117 | F18: 1 | G18: =F18*$O$8 -> 0.1405 | S18: =C25 -> 176.702 | T18: =S18*O9 -> 25.127024 | U18: =T18*R8 -> 6979.729
B19: Media Costo Galón | C19: 0 | D19: =$D$7 -> 4.2743998
B22: Historia de consumo de combustible y energía de la empresa 2022 | M22: Comportamiento del consumo de combustible expresado en Giga Joule de energía
M23: Consumo de Kerosene año 2022
B24: Mes | C24: Kerosene [gal] | D24: Total Energía [GJ] | J24: Días | K24: gal diarios
B25: ='Consumo Eléctrico'!B8 -> 44562 | C25: 176.702 | D25: =C25*$O$8 -> 24.826631 | F25: =D25*D5 -> 102531.06 | J25: ='Consumo Eléctrico'!E8 -> 31 | K25: =C25/J25 -> 5.7000645 | S25: Consumo [kwh]
B26: ='Consumo Eléctrico'!B9 -> 44593 | C26: 229.2886 | D26: =C26*$O$8 -> 32.215048 | J26: ='Consumo Eléctrico'!E9 -> 30 | K26: =C26/J26 -> 7.6429533 | S26: =D25*$R$8 -> 6896.2864
B27: ='Consumo Eléctrico'!B10 -> 44621 | C27: 239.4646 | D27: =C27*$O$8 -> 33.644776 | J27: ='Consumo Eléctrico'!E10 -> 30 | K27: =C27/J27 -> 7.9821533 | S27: =D26*$R$8 -> 8948.6245
B28: ='Consumo Eléctrico'!B11 -> 44652 | C28: 422.1238 | D28: =C28*$O$8 -> 59.308394 | J28: ='Consumo Eléctrico'!E11 -> 31 | K28: =C28/J28 -> 13.616897 | S28: =D27*$R$8 -> 9345.7712
B29: ='Consumo Eléctrico'!B12 -> 44682 | C29: 396.8852 | D29: =C29*$O$8 -> 55.762371 | J29: ='Consumo Eléctrico'!E12 -> 30 | K29: =C29/J29 -> 13.229507 | S29: =D28*$R$8 -> 16474.554
B30: ='Consumo Eléctrico'!B13 -> 44713 | C30: 401.7506 | D30: =C30*$O$8 -> 56.445959 | J30: ='Consumo Eléctrico'!E13 -> 31 | K30: =C30/J30 -> 12.959697 | S30: =D29*$R$8 -> 15489.547
B31: ='Consumo Eléctrico'!B14 -> 44743 | C31: 381.07 | D31: =C31*$O$8 -> 53.540335 | J31: ='Consumo Eléctrico'!E14 -> 30 | K31: =C31/J31 -> 12.702333 | S31: =D30*$R$8 -> 15679.433
B32: ='Consumo Eléctrico'!B15 -> 44774 | C32: 405.0578 | D32: =C32*$O$8 -> 56.910621 | J32: ='Consumo Eléctrico'!E15 -> 30 | K32: =C32/J32 -> 13.501927 | S32: =D31*$R$8 -> 14872.315
B33: ='Consumo Eléctrico'!B16 -> 44805 | C33: 173.5856 | D33: =C33*$O$8 -> 24.388777 | J33: ='Consumo Eléctrico'!E16 -> 30 | K33: =C33/J33 -> 5.7861867 | S33: =D32*$R$8 -> 15808.506
B34: ='Consumo Eléctrico'!B17 -> 44835 | C34: 172.45 | D34: =C34*$O$8 -> 24.229225 | J34: ='Consumo Eléctrico'!E17 -> 31 | K34: =C34/J34 -> 5.5629032 | S34: =D33*$R$8 -> 6774.6602
B35: ='Consumo Eléctrico'!B18 -> 44866 | C35: 330.9002 | D35: =C35*$O$8 -> 46.491478 | J35: ='Consumo Eléctrico'!E18 -> 31 | K35: =C35/J35 -> 10.6742 | S35: =D34*$R$8 -> 6730.3403
B36: ='Consumo Eléctrico'!B19 -> 44896 | C36: 115.911 | D36: =C36*$O$8 -> 16.285496 | J36: ='Consumo Eléctrico'!E19 -> 30 | K36: =C36/J36 -> 3.8637 | S36: =D35*$R$8 -> 12914.299
B37: Media Consumo mes | C37: =AVERAGE(C25:C36) -> 287.09912 | D37: =AVERAGE(D25:D36) -> 40.337426 | J37: =AVERAGE(J25:J36) -> 30.416667 | K37: =AVERAGE(K25:K36) -> 9.4352101 | S37: =D36*$R$8 -> 4523.7488
B38: Total (anual) 2022 | C38: =SUM(C25:C36) -> 3445.1894 | D38: =SUM(D25:D36) -> 484.04911 | S38: =AVERAGE(S26:S37) -> 11204.841
F39: =B24 -> Mes | G39: =D24 -> Total Energía [GJ] | S39: =SUM(S26:S37) -> 134458.09
F40: =B25 -> 44562 | G40: =D25 -> 24.826631
F41: =B26 -> 44593 | G41: =D26 -> 32.215048
F42: =B27 -> 44621 | G42: =D27 -> 33.644776
B43: Datos de consumo de combustible 2023 | F43: =B28 -> 44652 | G43: =D28 -> 59.308394
...

Sheet Indicadores Energéticos
B2: Indicadores Energéticos de empresa 2022 | N2: Indicadores Energéticos de empresa 2023
A4: Mes | B4: Consumo Energía Eléctrica [kWh/mes] | C4: Consumo Térmico [Gal Kerosene] | D4: Emulsión Asfáltica [m³/mes] | E4: Mezcla Asfáltica [m³] /mes | F4: kWh/m³ Emulsión | G4: kWh/m³ Mezcla | H4: kg CO₂/m³ Emulsión | I4: kg CO₂/m³ Mezcla | J4: Kerosene gal /m³ Emulsión | M4: Mes | N4: Consumo Energía Eléctrica [kWh] | O4: Consumo Térmico [Gal Kerosene] | P4: Emulsión Asfáltica [m³] | Q4: Mezcla Asfáltica [m³] | R4: kWh/m³ Emulsión | S4: kWh/m³ Mezcla | T4: kg CO₂/m³ Emulsión | U4: kg CO₂/m³ Mezcla | V4: Kerosene gal /m³ Emulsión | Z4: kWh/m³ Emulsión | AA4: kWh/m³ Mezcla | AB4: Kerosene gal /m³ Emulsión
A8: ='Consumo Eléctrico'!B8 -> 44562 | B8: ='Consumo Eléctrico'!I8 -> 8674.83 | C8: ='Consumo Térmico de la empresa'!C25 -> 176.702 | D8: 72.34458 | E8: 114.1602 | F8: =B8/D8 -> 119.90988 | G8: =B8/E8 -> 75.988217 | H8: =F8*$H$25 -> 28.586516 | I8: =G8*$H$25 -> 18.115591 | J8: =C8/D8 -> 2.442505 | M8: ='Consumo Eléctrico'!B20 -> 44927 | N8: ='Consumo Eléctrico'!I20 -> 8475 | O8: ='Consumo Térmico de la empresa'!C56 -> 165.03 | P8: 81.25 | Q8: 140.2 | R8: =N8/P8 -> 104.30769 | S8: =N8/Q8 -> 60.449358 | T8: =R8*$T$25 -> 24.866954 | U8: =S8*$T$25 -> 14.411127 | V8: =O8/P8 -> 2.0311385 | Z8: =AVERAGE(F21,R21) -> 975.30607 | AA8: =AVERAGE(G20,S20) -> 59.98047 | AB8: =AVERAGE(J20,V20) -> 2.0551352
A9: ='Consumo Eléctrico'!B9 -> 44593 | B9: ='Consumo Eléctrico'!I9 -> 9893.12 | C9: ='Consumo Térmico de la empresa'!C26 -> 229.2886 | D9: 99.4455 | E9: 194.39574 | F9: =B9/D9 -> 99.482832 | G9: =B9/E9 -> 50.89165 | H9: =F9*$H$25 -> 23.716707 | I9: =G9*$H$25 -> 12.132569 | J9: =C9/D9 -> 2.3056709 | M9: ='Consumo Eléctrico'!B21 -> 44958 | N9: ='Consumo Eléctrico'!I21 -> 8802.64 | O9: ='Consumo Térmico de la empresa'!C57 -> 224.9624 | P9: 104.56 | Q9: 225.66 | R9: =N9/P9 -> 84.187452 | S9: =N9/Q9 -> 39.00842 | T9: =R9*$T$25 -> 20.070289 | U9: =S9*$T$25 -> 9.2996073 | V9: =O9/P9 -> 2.1515149
A10: ='Consumo Eléctrico'!B10 -> 44621 | B10: ='Consumo Eléctrico'!I10 -> 9689.25 | C10: ='Consumo Térmico de la empresa'!C27 -> 239.4646 | D10: 104.69536 | E10: 57.60832 | F10: =B10/D10 -> 92.547081 | G10: =B10/E10 -> 168.19185 | H10: =F10*$H$25 -> 22.063224 | I10: =G10*$H$25 -> 40.096937 | J10: =C10/D10 -> 2.2872513 | M10: ='Consumo Eléctrico'!B22 -> 44986 | N10: ='Consumo Eléctrico'!I22 -> 9633.16 | O10: ='Consumo Térmico de la empresa'!C58 -> 234.9464 | P10: 117.89 | Q10: 54.56 | R10: =N10/P10 -> 81.713122 | S10: =N10/Q10 -> 176.56085 | T10: =R10*$T$25 -> 19.480408 | U10: =S10*$T$25 -> 42.092107 | V10: =O10/P10 -> 1.992929
A11: ='Consumo Eléctrico'!B11 -> 44652 | B11: ='Consumo Eléctrico'!I11 -> 9823.56 | C11: ='Consumo Térmico de la empresa'!C28 -> 422.1238 | D11: 198.85866 | E11: 80.99014 | F11: =B11/D11 -> 49.399709 | G11: =B11/E11 -> 121.29328 | H11: =F11*$H$25 -> 11.776891 | I11: =G11*$H$25 -> 28.916319 | J11: =C11/D11 -> 2.1227328 | M11: ='Consumo Eléctrico'!B23 -> 45017 | N11: ='Consumo Eléctrico'!I23 -> 9796.5 | O11: ='Consumo Térmico de la empresa'!C59 -> 414.1592 | P11: 214.56 | Q11: 91.56 | R11: =N11/P11 -> 45.658557 | S11: =N11/Q11 -> 106.99541 | T11: =R11*$T$25 -> 10.885 | U11: =S11*$T$25 -> 25.507706 | V11: =O11/P11 -> 1.9302722 | AB11: GJ /m³ Emulsión
A12: ='Consumo Eléctrico'!B12 -> 44682 | B12: ='Consumo Eléctrico'!I12 -> 10503.89 | C12: ='Consumo Térmico de la empresa'!C29 -> 396.8852 | D12: 265.41 | E12: 383.84346 | F12: =B12/D12 -> 39.57609 | G12: =B12/E12 -> 27.365036 | H12: =F12*$H$25 -> 9.4349398 | I12: =G12*$H$25 -> 6.5238245 | J12: =C12/D12 -> 1.4953664 | M12: ='Consumo Eléctrico'!B24 -> 45047 | N12: ='Consumo Eléctrico'!I24 -> 11503.69 | O12: ='Consumo Térmico de la empresa'!C60 -> 363.1874 | P12: 314.16 | Q12: 456.25 | R12: =N12/P12 -> 36.617297 | S12: =N12/Q12 -> 25.213567 | T12: =R12*$T$25 -> 8.7295636 | U12: =S12*$T$25 -> 6.0109144 | V12: =O12/P12 -> 1.1560587
A13: ='Consumo Eléctrico'!B13 -> 44713 | B13: ='Consumo Eléctrico'!I13 -> 9931.33 | C13: ='Consumo Térmico de la empresa'!C30 -> 401.7506 | D13: 188.35894 | E13: 102.21596 | F13: =B13/D13 -> 52.725557 | G13: =B13/E13 -> 97.160267 | H13: =F13*$H$25 -> 12.569773 | I13: =G13*$H$25 -> 23.163008 | J13: =C13/D13 -> 2.132899 | M13: ='Consumo Eléctrico'!B25 -> 45078 | N13: ='Consumo Eléctrico'!I25 -> 9636.34 | O13: ='Consumo Térmico de la empresa'!C61 -> 352.4793 | P13: 199.52 | Q13: 101.15 | R13: =N13/P13 -> 48.297614 | S13: =N13/Q13 -> 95.26782 | T13: =R13*$T$25 -> 11.514151 | U13: =S13*$T$25 -> 22.711848 | V13: =O13/P13 -> 1.7666364
A14: ='Consumo Eléctrico'!B14 -> 44743 | B14: ='Consumo Eléctrico'!I14 -> 9668.73 | C14: ='Consumo Térmico de la empresa'!C31 -> 381.07 | D14: 177.69752 | E14: 170.0006 | F14: =B14/D14 -> 54.41117 | G14: =B14/E14 -> 56.874682 | H14: =F14*$H$25 -> 12.971623 | I14: =G14*$H$25 -> 13.558924 | J14: =C14/D14 -> 2.1444869 | M14: ='Consumo Eléctrico'!B26 -> 45108 | N14: ='Consumo Eléctrico'!I26 -> 10051.65 | O14: ='Consumo Térmico de la empresa'!C62 -> 366.69 | P14: 212.12 | Q14: 160.52 | R14: =N14/P14 -> 47.386621 | S14: =N14/Q14 -> 62.6193 | T14: =R14*$T$25 -> 11.29697 | U14: =S14*$T$25 -> 14.928441 | V14: =O14/P14 -> 1.7286913
A15: ='Consumo Eléctrico'!B15 -> 44774 | B15: ='Consumo Eléctrico'!I15 -> 9498.13 | C15: ='Consumo Térmico de la empresa'!C32 -> 405.0578 | D15: 190.06218 | E15: 619.7422 | F15: =B15/D15 -> 49.973803 | G15: =B15/E15 -> 15.325937 | H15: =F15*$H$25 -> 11.913755 | I15: =G15*$H$25 -> 3.6537034 | J15: =C15/D15 -> 2.1311857 | M15: ='Consumo Eléctrico'!B27 -> 45139 | N15: ='Consumo Eléctrico'!I27 -> 8620.61 | O15: ='Consumo Térmico de la empresa'!C63 -> 389.7726 | P15: 112.32 | Q15: 685.25 | R15: =N15/P15 -> 76.750445 | S15: =N15/Q15 -> 12.580241 | T15: =R15*$T$25 -> 18.297306 | U15: =S15*$T$25 -> 2.9991294 | V15: =O15/P15 -> 3.4701976 | AB15: =AB8*'Consumo Térmico de la empresa'!O8 -> 0.28874649
A16: ='Consumo Eléctrico'!B16 -> 44805 | B16: ='Consumo Eléctrico'!I16 -> 9284.99 | C16: ='Consumo Térmico de la empresa'!C33 -> 173.5856 | D16: 118.91 | E16: 663.0778 | F16: =B16/D16 -> 78.084181 | G16: =B16/E16 -> 14.002867 | H16: =F16*$H$25 -> 18.615269 | I16: =G16*$H$25 -> 3.3382834 | J16: =C16/D16 -> 1.4598066 | M16: ='Consumo Eléctrico'!B28 -> 45170 | N16: ='Consumo Eléctrico'!I28 -> 9013.66 | O16: ='Consumo Térmico de la empresa'!C64 -> 167.0352 | P16: 81.5 | Q16: 701.25 | R16: =N16/P16 -> 110.59706 | S16: =N16/Q16 -> 12.853704 | T16: =R16*$T$25 -> 26.366338 | U16: =S16*$T$25 -> 3.0643231 | V16: =O16/P16 -> 2.0495117
A17: ='Consumo Eléctrico'!B17 -> 44835 | B17: ='Consumo Eléctrico'!I17 -> 9045.56 | C17: 172.45 | D17: 112 | E17: 291.34028 | F17: =B17/D17 -> 80.763929 | G17: =B17/E17 -> 31.048093 | H17: =F17*$H$25 -> 19.254121 | I17: =G17*$H$25 -> 7.4018653 | J17: =C17/D17 -> 1.5397321 | M17: ='Consumo Eléctrico'!B29 -> 45200 | N17: ='Consumo Eléctrico'!I29 -> 9003.9 | O17: 165.54 | P17: 70.14 | Q17: 301.56 | R17: =N17/P17 -> 128.3704 | S17: =N17/Q17 -> 29.85774 | T17: =R17*$T$25 -> 30.603504 | U17: =S17*$T$25 -> 7.1180852 | V17: =O17/P17 -> 2.3601369
A18: ='Consumo Eléctrico'!B18 -> 44866 | B18: ='Consumo Eléctrico'!I18 -> 9676.81 | C18: ='Consumo Térmico de la empresa'!C35 -> 330.9002 | D18: 151.82552 | E18: 658.03276 | F18: =B18/D18 -> 63.736386 | G18: =B18/E18 -> 14.705666 | H18: =F18*$H$25 -> 15.194755 | I18: =G18*$H$25 -> 3.5058308 | J18: =C18/D18 -> 2.1794768 | M18: ='Consumo Eléctrico'!B30 -> 45231 | N18: ='Consumo Eléctrico'!I30 -> 10060.05 | O18: ='Consumo Térmico de la empresa'!C66 -> 318.4134 | P18: 181.45 | Q18: 764.23 | R18: =N18/P18 -> 55.442546 | S18: =N18/Q18 -> 13.163642 | T18: =R18*$T$25 -> 13.217503 | U18: =S18*$T$25 -> 3.1382122 | V18: =O18/P18 -> 1.7548272
A19: ='Consumo Eléctrico'!B19 -> 44896 | B19: ='Consumo Eléctrico'!I19 -> 8577.93 | C19: ='Consumo Térmico de la empresa'!C36 -> 115.911 | D19: 41.00712 | E19: 118.65546 | F19: =B19/D19 -> 209.18148 | G19: =B19/E19 -> 72.292754 | H19: =F19*$H$25 -> 49.868865 | I19: =G19*$H$25 -> 17.234593 | J19: =C19/D19 -> 2.8266067 | M19: ='Consumo Eléctrico'!B31 -> 45261 | N19: ='Consumo Eléctrico'!I31 -> 8468.25 | O19: ='Consumo Térmico de la empresa'!C67 -> 111.537 | P19: 59.85 | Q19: 141.56 | R19: =N19/P19 -> 141.49123 | S19: =N19/Q19 -> 59.820924 | T19: =R19*$T$25 -> 33.731509 | U19: =S19*$T$25 -> 14.261308 | V19: =O19/P19 -> 1.863609
A20: Media | B20: =AVERAGE(B8:B19) -> 9522.3442 | C20: =AVERAGE(C8:C19) -> 287.09912 | D20: =AVERAGE(D8:D19) -> 143.38462 | E20: =AVERAGE(E8:E19) -> 287.83858 | F20: =AVERAGE(F8:F19) -> 82.482675 | G20: =AVERAGE(G8:G19) -> 62.095025 | H20: =AVERAGE(H8:H19) -> 19.66387 | I20: =AVERAGE(I8:I19) -> 14.803454 | J20: =AVERAGE(J8:J19) -> 2.0889767 | M20: Media | N20: =AVERAGE(N8:N19) -> 9422.1208 | O20: =AVERAGE(O8:O19) -> 272.81274 | P20: =AVERAGE(P8:P19) -> 145.77667 | Q20: =AVERAGE(Q8:Q19) -> 318.64583 | R20: =AVERAGE(R8:R19) -> 80.068336 | S20: =AVERAGE(S8:S19) -> 57.865915 | T20: =AVERAGE(T8:T19) -> 19.088291 | U20: =AVERAGE(U8:U19) -> 13.795234 | V20: =AVERAGE(V8:V19) -> 2.0212936
A21: Total | B21: =SUM(B8:B19) -> 114268.13 | C21: =SUM(C8:C19) -> 3445.1894 | D21: =SUM(D8:D19) -> 1720.6154 | E21: =SUM(E8:E19) -> 3454.0629 | F21: =SUM(F8:F19) -> 989.7921 | G21: =SUM(G8:G19) -> 745.1403 | H21: =SUM(H8:H19) -> 235.96644 | I21: =SUM(I8:I19) -> 177.64145 | J21: =SUM(J8:J19) -> 25.06772 | M21: Total | N21: =SUM(N8:N19) -> 113065.45 | O21: =SUM(O8:O19) -> 3273.7529 | P21: =SUM(P8:P19) -> 1749.32 | Q21: =SUM(Q8:Q19) -> 3823.75 | R21: =SUM(R8:R19) -> 960.82003 | S21: =SUM(S8:S19) -> 694.39098 | T21: =SUM(T8:T19) -> 229.0595 | U21: =SUM(U8:U19) -> 165.54281 | V21: =SUM(V8:V19) -> 24.255523
R23: =AVERAGE(F20,R20) -> 81.275505
H24: factor | I24: directo pgf | T24: factor | U24: directo pgf
H25: 0.2384 | T25: 0.2384
O29: Mes | P29: =B4 -> Consumo Energía Eléctrica [kWh/mes] | Q29: Consumo Predicho línea base | R29: Diferencia | S29: Concepto
O30: 1 | P30: =B8 -> 8674.83 | Q30: =-87.831*O30+10325 -> 10237.169 | R30: =P30-Q30 -> -1562.339 | S30: =IF(R30>0,"Sobre Consumo","-") -> - | AB30: Análisis previo Linea Base de Consumo Energético - PGF
O31: 2 | P31: =B9 -> 9893.12 | Q31: =-87.831*O31+10325 -> 10149.338 | R31: =P31-Q31 -> -256.218 | S31: =IF(R31>0,"Sobre Consumo","-") -> -
O32: 3 | P32: =B10 -> 9689.25 | Q32: =-87.831*O32+10325 -> 10061.507 | R32: =P32-Q32 -> -372.257 | S32: =IF(R32>0,"Sobre Consumo","-") -> -
O33: 4 | P33: =B11 -> 9823.56 | Q33: =-87.831*O33+10325 -> 9973.676 | R33: =P33-Q33 -> -150.116 | S33: =IF(R33>0,"Sobre Consumo","-") -> -
O34: 5 | P34: =B12 -> 10503.89 | Q34: =-87.831*O34+10325 -> 9885.845 | R34: =P34-Q34 -> 618.045 | S34: =IF(R34>0,"Sobre Consumo","-") -> Sobre Consumo
O35: 6 | P35: =B13 -> 9931.33 | Q35: =-87.831*O35+10325 -> 9798.014 | R35: =P35-Q35 -> 133.316 | S35: =IF(R35>0,"Sobre Consumo","-") -> Sobre Consumo
O36: 7 | P36: =B14 -> 9668.73 | Q36: =-87.831*O36+10325 -> 9710.183 | R36: =P36-Q36 -> -41.453 | S36: =IF(R36>0,"Sobre Consumo","-") -> -
O37: 8 | P37: =B15 -> 9498.13 | Q37: =-87.831*O37+10325 -> 9622.352 | R37: =P37-Q37 -> -124.222 | S37: =IF(R37>0,"Sobre Consumo","-") -> -
O38: 9 | P38: =B16 -> 9284.99 | Q38: =-87.831*O38+10325 -> 9534.521 | R38: =P38-Q38 -> -249.531 | S38: =IF(R38>0,"Sobre Consumo","-") -> -
O39: 10 | P39: =B17 -> 9045.56 | Q39: =-87.831*O39+10325 -> 9446.69 | R39: =P39-Q39 -> -401.13 | S39: =IF(R39>0,"Sobre Consumo","-") -> -
O40: 11 | P40: =B18 -> 9676.81 | Q40: =-87.831*O40+10325 -> 9358.859 | R40: =P40-Q40 -> 317.951 | S40: =IF(R40>0,"Sobre Consumo","-") -> Sobre Consumo
O41: 12 | P41: =B19 -> 8577.93 | Q41: =-87.831*O41+10325 -> 9271.028 | R41: =P41-Q41 -> -693.098 | S41: =IF(R41>0,"Sobre Consumo","-") -> -
J47: [kWh] | K47: [m³] | X47: [kWh] | Y47: [m³]
I48: =A8 -> 44562 | J48: =B8/100 -> 86.7483 | K48: =D8 -> 72.34458 | W48: =M8 -> 44927 | X48: =N8/100 -> 84.75 | Y48: =P8 -> 81.25
B49: Comportamiento de indicador de desempeño energético para emulsión asfáltica | I49: =A9 -> 44593 | J49: =B9/100 -> 98.9312 | K49: =D9 -> 99.4455 | W49: =M9 -> 44958 | X49: =N9/100 -> 88.0264 | Y49: =P9 -> 104.56
I50: =A10 -> 44621 | J50: =B10/100 -> 96.8925 | K50: =D10 -> 104.69536 | W50: =M10 -> 44986 | X50: =N10/100 -> 96.3316 | Y50: =P10 -> 117.89
I51: =A11 -> 44652 | J51: =B11/100 -> 98.2356 | K51: =D11 -> 198.85866 | W51: =M11 -> 45017 | X51: =N11/100 -> 97.965 | Y51: =P11 -> 214.56
I52: =A12 -> 44682 | J52: =B12/100 -> 105.0389 | K52: =D12 -> 265.41 | W52: =M12 -> 45047 | X52: =N12/100 -> 115.0369 | Y52: =P12 -> 314.16
I53: =A13 -> 44713 | J53: =B13/100 -> 99.3133 | K53: =D13 -> 188.35894 | W53: =M13 -> 45078 | X53: =N13/100 -> 96.3634 | Y53: =P13 -> 199.52
I54: =A14 -> 44743 | J54: =B14/100 -> 96.6873 | K54: =D14 -> 177.69752 | W54: =M14 -> 45108 | X54: =N14/100 -> 100.5165 | Y54: =P14 -> 212.12
...

Sheet Emisiones de GEI
D4: Ton de CO₂/MWh (factor por emisión de combustible) | L4: Ton de CO₂/MWh (factor por emisión de combustible)
Q5: Factor de emisiones GEI del Sistema Eléctrico Nacional
D6: factor | F6: emisión [Kg CO₂] | L6: factor | N6: emisión [Kg CO₂] | Q6: https://energia.gob.cl/indicadores-ambientales-factor-de-emisiones-gei-del-sistema-electrico-nacional
C7: =C35 -> 8674.83 | D7: =D52 -> 0.2384 | F7: =C7*D7 -> 2068.0795 | K7: =K35 -> 8475 | L7: =L52 -> 0.2384 | N7: =K7*L7 -> 2020.44
F8: emisión [Ton CO₂] | N8: emisión [Ton CO₂]
F9: =F7/1000 -> 2.0680795 | N9: =N7/1000 -> 2.02044 | Q9: Factor de conversión de GJ a kW
Q10: https://es.converterin.com/economia-de-combustible/gigajoule-to-us-galones-de-kerosene.html
D11: factor | F11: emisión [Ton CO₂] | L11: factor | N11: emisión [Ton CO₂] | Q11: =277.77777778 -> 277.77778
C12: =C35 -> 8674.83 | D12: =D52 -> 0.2384 | F12: =C12*D12/1000 -> 2.0680795 | K12: =K35 -> 8475 | L12: =L52 -> 0.2384 | N12: =K12*L12/1000 -> 2.02044
D15: factor | F15: emisión [Kg CO₂] | L15: factor | N15: emisión [Kg CO₂]
C16: =C35 -> 8674.83 | D16: =D52 -> 0.2384 | F16: =C16*D16 -> 2068.0795 | K16: =K35 -> 8475 | L16: =L52 -> 0.2384 | N16: =K16*L16 -> 2020.44
F17: emisión [Ton CO₂] | N17: emisión [Ton CO₂]
F18: =F16/1000 -> 2.0680795 | N18: =N16/1000 -> 2.02044
C28: Emisiones totales de la empresa 2022 | K28: Emisiones totales de la empresa 2023
D30: Calcular | G30: Calcular | L30: Calcular | O30: Calcular
B31: Mes | C31: Consumo Energía Eléctrica [kWh] | D31: Emisiones totales por consumo eléctrico [Ton CO₂] | F31: Consumo Energía Térmica [GJ] | G31: Emisiones totales por consumo térmico [Ton CO₂] | J31: Mes | K31: Consumo Energía Eléctrica [kWh] | L31: Emisiones totales por consumo eléctrico [Ton CO₂] | N31: Consumo Energía Térmica [GJ] | O31: Emisiones totales por consumo térmico [Ton CO₂]
B35: ='Consumo Eléctrico'!B8 -> 44562 | C35: ='Consumo Eléctrico'!I8 -> 8674.83 | D35: =C35*$D$52/1000 -> 2.0680795 | F35: ='Consumo Térmico de la empresa'!D25 -> 24.826631 | G35: =F35*$Q$11*$G$53/1000 -> 1.7850348 | J35: ='Consumo Eléctrico'!B20 -> 44927 | K35: ='Consumo Eléctrico'!I20 -> 8475 | L35: =K35*$L$52/1000 -> 2.02044 | N35: ='Consumo Térmico de la empresa'!D56 -> 23.186715 | O35: =N35*$Q$11*$G$53/1000 -> 1.6671248
B36: ='Consumo Eléctrico'!B9 -> 44593 | C36: ='Consumo Eléctrico'!I9 -> 9893.12 | D36: =C36*$D$52/1000 -> 2.3585198 | F36: ='Consumo Térmico de la empresa'!D26 -> 32.215048 | G36: =F36*$Q$11*$G$53/1000 -> 2.316262 | J36: ='Consumo Eléctrico'!B21 -> 44958 | K36: ='Consumo Eléctrico'!I21 -> 8802.64 | L36: =K36*$L$52/1000 -> 2.0985494 | N36: ='Consumo Térmico de la empresa'!D57 -> 31.607217 | O36: =N36*$Q$11*$G$53/1000 -> 2.2725589
B37: ='Consumo Eléctrico'!B10 -> 44621 | C37: ='Consumo Eléctrico'!I10 -> 9689.25 | D37: =C37*$D$52/1000 -> 2.3099172 | F37: ='Consumo Térmico de la empresa'!D27 -> 33.644776 | G37: =F37*$Q$11*$G$53/1000 -> 2.4190594 | J37: ='Consumo Eléctrico'!B22 -> 44986 | K37: ='Consumo Eléctrico'!I22 -> 9633.16 | L37: =K37*$L$52/1000 -> 2.2965453 | N37: ='Consumo Térmico de la empresa'!D58 -> 33.009969 | O37: =N37*$Q$11*$G$53/1000 -> 2.3734168
B38: ='Consumo Eléctrico'!B11 -> 44652 | C38: ='Consumo Eléctrico'!I11 -> 9823.56 | D38: =C38*$D$52/1000 -> 2.3419367 | F38: ='Consumo Térmico de la empresa'!D28 -> 59.308394 | G38: =F38*$Q$11*$G$53/1000 -> 4.2642735 | J38: ='Consumo Eléctrico'!B23 -> 45017 | K38: ='Consumo Eléctrico'!I23 -> 9796.5 | L38: =K38*$L$52/1000 -> 2.3354856 | N38: ='Consumo Térmico de la empresa'!D59 -> 58.189368 | O38: =N38*$Q$11*$G$53/1000 -> 4.1838155
B39: ='Consumo Eléctrico'!B12 -> 44682 | C39: ='Consumo Eléctrico'!I12 -> 10503.89 | D39: =C39*$D$52/1000 -> 2.5041274 | F39: ='Consumo Térmico de la empresa'!D29 -> 55.762371 | G39: =F39*$Q$11*$G$53/1000 -> 4.0093144 | J39: ='Consumo Eléctrico'!B24 -> 45047 | K39: ='Consumo Eléctrico'!I24 -> 11503.69 | L39: =K39*$L$52/1000 -> 2.7424797 | N39: ='Consumo Térmico de la empresa'!D60 -> 51.02783 | O39: =N39*$Q$11*$G$53/1000 -> 3.668901
B40: ='Consumo Eléctrico'!B13 -> 44713 | C40: ='Consumo Eléctrico'!I13 -> 9931.33 | D40: =C40*$D$52/1000 -> 2.3676291 | F40: ='Consumo Térmico de la empresa'!D30 -> 56.445959 | G40: =F40*$Q$11*$G$53/1000 -> 4.0584645 | J40: ='Consumo Eléctrico'!B25 -> 45078 | K40: ='Consumo Eléctrico'!I25 -> 9636.34 | L40: =K40*$L$52/1000 -> 2.2973035 | N40: ='Consumo Térmico de la empresa'!D61 -> 49.523342 | O40: =N40*$Q$11*$G$53/1000 -> 3.5607283
B41: ='Consumo Eléctrico'!B14 -> 44743 | C41: ='Consumo Eléctrico'!I14 -> 9668.73 | D41: =C41*$D$52/1000 -> 2.3050252 | F41: ='Consumo Térmico de la empresa'!D31 -> 53.540335 | G41: =F41*$Q$11*$G$53/1000 -> 3.8495501 | J41: ='Consumo Eléctrico'!B26 -> 45108 | K41: ='Consumo Eléctrico'!I26 -> 10051.65 | L41: =K41*$L$52/1000 -> 2.3963134 | N41: ='Consumo Térmico de la empresa'!D62 -> 51.519945 | O41: =N41*$Q$11*$G$53/1000 -> 3.704284
B42: ='Consumo Eléctrico'!B15 -> 44774 | C42: ='Consumo Eléctrico'!I15 -> 9498.13 | D42: =C42*$D$52/1000 -> 2.2643542 | F42: ='Consumo Térmico de la empresa'!D32 -> 56.910621 | G42: =F42*$Q$11*$G$53/1000 -> 4.0918736 | J42: ='Consumo Eléctrico'!B27 -> 45139 | K42: ='Consumo Eléctrico'!I27 -> 8620.61 | L42: =K42*$L$52/1000 -> 2.0551534 | N42: ='Consumo Térmico de la empresa'!D63 -> 54.76305 | O42: =N42*$Q$11*$G$53/1000 -> 3.9374633
B43: ='Consumo Eléctrico'!B16 -> 44805 | C43: ='Consumo Eléctrico'!I16 -> 9284.99 | D43: =C43*$D$52/1000 -> 2.2135416 | F43: ='Consumo Térmico de la empresa'!D33 -> 24.388777 | G43: =F43*$Q$11*$G$53/1000 -> 1.7535531 | J43: ='Consumo Eléctrico'!B28 -> 45170 | K43: ='Consumo Eléctrico'!I28 -> 9013.66 | L43: =K43*$L$52/1000 -> 2.1488565 | N43: ='Consumo Térmico de la empresa'!D64 -> 23.468446 | O43: =N43*$Q$11*$G$53/1000 -> 1.6873812
B44: ='Consumo Eléctrico'!B17 -> 44835 | C44: ='Consumo Eléctrico'!I17 -> 9045.56 | D44: =C44*$D$52/1000 -> 2.1564615 | F44: ='Consumo Térmico de la empresa'!D34 -> 24.229225 | G44: =F44*$Q$11*$G$53/1000 -> 1.7420813 | J44: ='Consumo Eléctrico'!B29 -> 45200 | K44: ='Consumo Eléctrico'!I29 -> 9003.9 | L44: =K44*$L$52/1000 -> 2.1465298 | N44: ='Consumo Térmico de la empresa'!D65 -> 23.25837 | O44: =N44*$Q$11*$G$53/1000 -> 1.6722768
B45: ='Consumo Eléctrico'!B18 -> 44866 | C45: ='Consumo Eléctrico'!I18 -> 9676.81 | D45: =C45*$D$52/1000 -> 2.3069515 | F45: ='Consumo Térmico de la empresa'!D35 -> 46.491478 | G45: =F45*$Q$11*$G$53/1000 -> 3.3427373 | J45: ='Consumo Eléctrico'!B30 -> 45231 | K45: ='Consumo Eléctrico'!I30 -> 10060.05 | L45: =K45*$L$52/1000 -> 2.3983159 | N45: ='Consumo Térmico de la empresa'!D66 -> 44.737083 | O45: =N45*$Q$11*$G$53/1000 -> 3.2165962
B46: ='Consumo Eléctrico'!B19 -> 44896 | C46: ='Consumo Eléctrico'!I19 -> 8577.93 | D46: =C46*$D$52/1000 -> 2.0449785 | F46: ='Consumo Térmico de la empresa'!D36 -> 16.285496 | G46: =F46*$Q$11*$G$53/1000 -> 1.1709271 | J46: ='Consumo Eléctrico'!B31 -> 45261 | K46: ='Consumo Eléctrico'!I31 -> 8468.25 | L46: =K46*$L$52/1000 -> 2.0188308 | N46: ='Consumo Térmico de la empresa'!D67 -> 15.670948 | O46: =N46*$Q$11*$G$53/1000 -> 1.1267412
B47: Media | C47: =AVERAGE(C35:C46) -> 9522.3442 | D47: =AVERAGE(D35:D46) -> 2.2701268 | F47: =AVERAGE(F35:F46) -> 40.337426 | G47: =AVERAGE(G35:G46) -> 2.9002609 | J47: Media | K47: =AVERAGE(K35:K46) -> 9422.1208 | L47: =AVERAGE(L35:L46) -> 2.2462336 | N47: =AVERAGE(N35:N46) -> 38.33019 | O47: =AVERAGE(O35:O46) -> 2.7559407
B48: Total | C48: =SUM(C35:C46) -> 114268.13 | D48: =SUM(D35:D46) -> 27.241522 | F48: =SUM(F35:F46) -> 484.04911 | G48: =SUM(G35:G46) -> 34.803131 | J48: Total | K48: =SUM(K35:K46) -> 113065.45 | L48: =SUM(L35:L46) -> 26.954803 | N48: =SUM(N35:N46) -> 459.96228 | O48: =SUM(O35:O46) -> 33.071288
D49: ✓ | G49: ✓
D51: factor | G51: factor | L51: factor | O51: factor
D52: ='Indicadores Energéticos'!H25 -> 0.2384 | L52: ='Indicadores Energéticos'!T25 -> 0.2384
G53: 0.25884 | O53: 0.2584
G54: 0.298 | O54: 0.298
F56: =F48 -> 484.04911 | G56: =F56*$Q$11*$G$53/1000 -> 34.803131
D58: Desde Propuesta de Mejora | F58: ='Propuesta de Mejora'!C529 -> 877.3822 | G58: =F58*$Q$11*G53/1000 -> 63.08378 | H58: ='Propuesta de Mejora'!C532 -> 63.08378
F59: =F58 -> 877.3822 | G59: =F59*$Q$11*$G$53/1000 -> 63.08378
F60: =F59 -> 877.3822 | G60: =F60*$Q$11*$G$53/1000 -> 63.08378

Sheet Cuantificador
C1: Inventario de motores de la empresa | R1: Inventario de motores de la empresa
B3: Área | C3: Descripción | D3: Capacidad instalada [kW] | E3: Hora de uso diario | F3: Factor de carga | G3: [Kwh]/día | H3: [Kwh]/mes | I3: [Kwh]/año | Q3: Área | R3: Descripción | S3: Capacidad instalada [kW] | T3: Hora de uso diario | U3: Factor de carga | V3: [Kwh]/día | W3: [Kwh]/mes | X3: [Kwh]/año
B4: Agua jabonosa y aditivos | C4: Bomba de pozo | D4: 0.7 | E4: 4 | F4: 0.9 | G4: =D4*E4*F4 -> 2.52 | H4: =G4*5 -> 12.6 | I4: =H4*12 -> 151.2 | J4: ✓ | Q4: Agua jabonosa y aditivos | R4: Bomba de pozo | S4: 0.7 | T4: 4 | U4: 0.9 | V4: =S4*T4*U4 -> 2.52 | W4: =V4*5 -> 12.6 | X4: =W4*12 -> 151.2 | Y4: ✓
C5: Bomba mezclador | D5: 5.6 | E5: 4 | F5: 0.9 | G5: =D5*E5*F5 -> 20.16 | H5: =G5*5 -> 100.8 | I5: =H5*12 -> 1209.6 | J5: ✓ | R5: Bomba mezclador | S5: 5.6 | T5: 4 | U5: 0.9 | V5: =S5*T5*U5 -> 20.16 | W5: =V5*5 -> 100.8 | X5: =W5*12 -> 1209.6 | Y5: ✓
C6: Bomba para ácido | D6: 1.5 | E6: 4 | F6: 0.9 | G6: =D6*E6*F6 -> 5.4 | H6: =G6*5 -> 27 | I6: =H6*12 -> 324 | J6: ✓ | R6: Bomba para ácido | S6: 1.5 | T6: 4 | U6: 0.9 | V6: =S6*T6*U6 -> 5.4 | W6: =V6*5 -> 27 | X6: =W6*12 -> 324 | Y6: ✓
C7: Bomba para jabón (estanque de preparación) | D7: 3 | E7: 4 | F7: 0.9 | G7: =D7*E7*F7 -> 10.8 | H7: =G7*5 -> 54 | I7: =H7*12 -> 648 | J7: ✓ | R7: Bomba para jabón (estanque de preparación) | S7: 3 | T7: 4 | U7: 0.9 | V7: =S7*T7*U7 -> 10.8 | W7: =V7*5 -> 54 | X7: =W7*12 -> 648 | Y7: ✓
C8: Bomba de kereosene (calentar agua) | D8: 0.2 | E8: 4 | F8: 0.9 | G8: =D8*E8*F8 -> 0.72 | H8: =G8*5 -> 3.6 | I8: =H8*12 -> 43.2 | J8: ✓ | R8: Bomba de kereosene (calentar agua) | S8: 0.2 | T8: 4 | U8: 0.9 | V8: =S8*T8*U8 -> 0.72 | W8: =V8*5 -> 3.6 | X8: =W8*12 -> 43.2 | Y8: ✓
C9: Bomba de jabón (agua preparada) | D9: 2.2 | E9: 4 | F9: 0.9 | G9: =D9*E9*F9 -> 7.92 | H9: =G9*5 -> 39.6 | I9: =H9*12 -> 475.2 | J9: ✓ | R9: Bomba de jabón (agua preparada) | S9: 2.2 | T9: 4 | U9: 0.9 | V9: =S9*T9*U9 -> 7.92 | W9: =V9*5 -> 39.6 | X9: =W9*12 -> 475.2 | Y9: ✓
C10: Motor rotador emulsión | D10: 8.2 | E10: 4 | F10: 0.9 | G10: =D10*E10*F10 -> 29.52 | H10: =G10*5 -> 147.6 | I10: =H10*12 -> 1771.2 | J10: ✓ | R10: Motor rotador emulsión | S10: 8.2 | T10: 4 | U10: 0.9 | V10: =S10*T10*U10 -> 29.52 | W10: =V10*5 -> 147.6 | X10: =W10*12 -> 1771.2 | Y10: ✓
B11: Emulsión | C11: Bomba de asfalto ex | D11: 3.7 | E11: 4 | F11: 0.9 | G11: =D11*E11*F11 -> 13.32 | H11: =G11*5 -> 66.6 | I11: =H11*12 -> 799.2 | J11: ✓ | Q11: Emulsión | R11: Bomba de asfalfo ex | S11: 3.7 | T11: 4 | U11: 0.9 | V11: =S11*T11*U11 -> 13.32 | W11: =V11*5 -> 66.6 | X11: =W11*12 -> 799.2 | Y11: ✓
C12: Bomba de asfalto in | D12: 11.2 | E12: 4 | F12: 0.9 | G12: =D12*E12*F12 -> 40.32 | H12: =G12*5 -> 201.6 | I12: =H12*12 -> 2419.2 | J12: ✓ | R12: Bomba de asfalto in | S12: 11.2 | T12: 4 | U12: 0.9 | V12: =S12*T12*U12 -> 40.32 | W12: =V12*5 -> 201.6 | X12: =W12*12 -> 2419.2 | Y12: ✓
C13: Motor aceite térmico | D13: 1.3 | E13: 4 | F13: 0.9 | G13: =D13*E13*F13 -> 4.68 | H13: =G13*5 -> 23.4 | I13: =H13*12 -> 280.8 | J13: ✓ | R13: Motor aceite térmico | S13: 1.3 | T13: 4 | U13: 0.9 | V13: =S13*T13*U13 -> 4.68 | W13: =V13*5 -> 23.4 | X13: =W13*12 -> 280.8 | Y13: ✓
B14: Almacenamiento | C14: Bomba de emulsión | D14: 5.6 | E14: 4 | F14: 0.9 | G14: =D14*E14*F14 -> 20.16 | H14: =G14*5 -> 100.8 | I14: =H14*12 -> 1209.6 | J14: ✓ | Q14: Almacenamiento | R14: Bomba de emulsión | S14: 5.6 | T14: 4 | U14: 0.9 | V14: =S14*T14*U14 -> 20.16 | W14: =V14*5 -> 100.8 | X14: =W14*12 -> 1209.6 | Y14: ✓
B15: Nodriza | C15: Motor de mezcladora | D15: 22.4 | E15: 4 | F15: 0.9 | G15: =D15*E15*F15 -> 80.64 | H15: =G15*5 -> 403.2 | I15: =H15*12 -> 4838.4 | J15: ✓ | Q15: Nodriza | R15: Motor de mezcladora | S15: 22.4 | T15: 4 | U15: 0.9 | V15: =S15*T15*U15 -> 80.64 | W15: =V15*5 -> 403.2 | X15: =W15*12 -> 4838.4 | Y15: ✓
C16: Bomba de emulsiones | D16: 7.5 | E16: 4 | F16: 0.9 | G16: =D16*E16*F16 -> 27 | H16: =G16*5 -> 135 | I16: =H16*12 -> 1620 | J16: ✓ | R16: Bomba de emulsiones | S16: 7.5 | T16: 4 | U16: 0.9 | V16: =S16*T16*U16 -> 27 | W16: =V16*5 -> 135 | X16: =W16*12 -> 1620 | Y16: ✓
C17: Motor de reductores 3/8 | D17: 1.5 | E17: 4 | F17: 0.9 | G17: =D17*E17*F17 -> 5.4 | H17: =G17*5 -> 27 | I17: =H17*12 -> 324 | J17: ✓ | R17: Motor de reductores 3/8 | S17: 1.5 | T17: 4 | U17: 0.9 | V17: =S17*T17*U17 -> 5.4 | W17: =V17*5 -> 27 | X17: =W17*12 -> 324 | Y17: ✓
C18: Motor de reductores 3/4 | D18: 1.5 | E18: 4 | F18: 0.9 | G18: =D18*E18*F18 -> 5.4 | H18: =G18*5 -> 27 | I18: =H18*12 -> 324 | J18: ✓ | R18: Motor de reductores 3/4 | S18: 1.5 | T18: 4 | U18: 0.9 | V18: =S18*T18*U18 -> 5.4 | W18: =V18*5 -> 27 | X18: =W18*12 -> 324 | Y18: ✓
C19: Motor reductor de chispa | D19: 1.5 | E19: 4 | F19: 0.9 | G19: =D19*E19*F19 -> 5.4 | H19: =G19*5 -> 27 | I19: =H19*12 -> 324 | J19: ✓ | R19: Motor reductor de chispa | S19: 1.5 | T19: 4 | U19: 0.9 | V19: =S19*T19*U19 -> 5.4 | W19: =V19*5 -> 27 | X19: =W19*12 -> 324 | Y19: ✓
C20: Motor banda transportadora | D20: 1.6 | E20: 4 | F20: 0.9 | G20: =D20*E20*F20 -> 5.76 | H20: =G20*5 -> 28.8 | I20: =H20*12 -> 345.6 | J20: ✓ | R20: Motor banda transportadora | S20: 1.6 | T20: 4 | U20: 0.9 | V20: =S20*T20*U20 -> 5.76 | W20: =V20*5 -> 28.8 | X20: =W20*12 -> 345.6 | Y20: ✓
C21: Bomba de agua | D21: 1.5 | E21: 4 | F21: 0.9 | G21: =D21*E21*F21 -> 5.4 | H21: =G21*5 -> 27 | I21: =H21*12 -> 324 | J21: ✓ | R21: Bomba de agua | S21: 1.5 | T21: 4 | U21: 0.9 | V21: =S21*T21*U21 -> 5.4 | W21: =V21*5 -> 27 | X21: =W21*12 -> 324 | Y21: ✓
C22: Bomba de asfalto | D22: 0.7 | E22: 4 | F22: 0.9 | G22: =D22*E22*F22 -> 2.52 | H22: =G22*5 -> 12.6 | I22: =H22*12 -> 151.2 | J22: ✓ | R22: Bomba de asfalto | S22: 0.7 | T22: 4 | U22: 0.9 | V22: =S22*T22*U22 -> 2.52 | W22: =V22*5 -> 12.6 | X22: =W22*12 -> 151.2 | Y22: ✓
C23: Bomba contra incendio | D23: 3 | E23: 4 | F23: 0.9 | G23: =D23*E23*F23 -> 10.8 | H23: =G23*5 -> 54 | I23: =H23*12 -> 648 | J23: ✓ | R23: Bomba contra incendio | S23: 3 | T23: 4 | U23: 0.9 | V23: =S23*T23*U23 -> 10.8 | W23: =V23*5 -> 54 | X23: =W23*12 -> 648 | Y23: ✓
C24: Total | D24: =SUM(D4:D23) -> 84.4 | G24: =SUM(G4:G23) -> 303.84 | H24: =SUM(H4:H23) -> 1519.2 | I24: =SUM(I4:I23) -> 18230.4 | R24: Total | S24: =SUM(S4:S23) -> 84.4 | V24: =SUM(V4:V23) -> 303.84 | W24: =SUM(W4:W23) -> 1519.2 | X24: =SUM(X4:X23) -> 18230.4
C31: Datos de consumo eléctrico de molino coloidal | R31: Datos de consumo eléctrico de molino coloidal
B33: Área | C33: Descripción | D33: Capacidad instalada [kW] | E33: Hora de uso diario | F33: Factor de carga | G33: [KWh]/día | H33: [KWh]/mes | I33: [KWh]/año | Q33: Área | R33: Descripción | S33: Capacidad instalada [kW] | T33: Hora de uso diario | U33: Factor de carga | V33: [Kwh]/día | W33: [Kwh]/mes | X33: [Kwh]/año
B34: Emulsión | C34: Molino coloidal | D34: 37.29 | E34: 4 | F34: 0.9 | G34: =D34*E34*F34 -> 134.244 | H34: =G34*5 -> 671.22 | I34: =H34*12 -> 8054.64 | Q34: Emulsión | R34: Molino coloidal | S34: 37.29 | T34: 4 | U34: 0.9 | V34: =S34*T34*U34 -> 134.244 | W34: =V34*5 -> 671.22 | X34: =W34*12 -> 8054.64 | Y34: ✓
C37: Inventario de aires acondicionados de la empresa | R37: Inventario de aires acondicionados de la empresa
B39: Área | C39: Tipo | D39: Capacidad [BTU/h] | E39: Potencia [kW] | F39: EER | G39: Horas Semana | H39: Horas año | I39: Consumo anual [kWh/año] | Q39: Área | R39: Tipo | S39: Capacidad [BTU/h] | T39: Potencia [kW] | U39: EER | V39: Horas Semana | W39: Horas año | X39: Consumo anual [kWh/año]
B40: Lab. de Control | C40: Mini Split | D40: 12000 | E40: 1.26 | F40: =D40/E40/1000 -> 9.5238095 | G40: 60 | H40: =G40*52 -> 3120 | I40: =G40*48*E40*0.8*0.81 -> 2351.4624 | Q40: Lab. de Control | R40: Mini Split | S40: 12000 | T40: 1.26 | U40: =S40/T40/1000 -> 9.5238095 | V40: 60 | W40: =V40*52 -> 3120 | X40: =V40*48*T40*0.8*0.81 -> 2351.4624 | Y40: ✓
B41: Lab. de Control | C41: Central | D41: 60000 | E41: 7.5 | F41: =D41/E41/1000 -> 8 | G41: 60 | H41: =G41*52 -> 3120 | I41: =G41*48*E41*0.8*0.81 -> 13996.8 | Q41: Lab. de Control | R41: Central | S41: 60000 | T41: 7.5 | U41: =S41/T41/1000 -> 8 | V41: 60 | W41: =V41*52 -> 3120 | X41: =V41*48*T41*0.8*0.81 -> 13996.8 | Y41: ✓
B42: Lab. de Suelos | C42: Central | D42: 60000 | E42: 7.5 | F42: =D42/E42/1000 -> 8 | G42: 60 | H42: =G42*52 -> 3120 | I42: =G42*48*E42*0.8*0.81 -> 13996.8 | Q42: Lab. de Suelos | R42: Central | S42: 60000 | T42: 7.5 | U42: =S42/T42/1000 -> 8 | V42: 60 | W42: =V42*52 -> 3120 | X42: =V42*48*T42*0.8*0.81 -> 13996.8 | Y42: ✓
B43: Oficinas 1 | C43: Mini Split | D43: 12000 | E43: 1.3 | F43: =D43/E43/1000 -> 9.2307692 | G43: 60 | H43: =G43*52 -> 3120 | I43: =G43*48*E43*0.8*0.81 -> 2426.112 | Q43: Oficinas 1 | R43: Mini Split | S43: 12000 | T43: 1.3 | U43: =S43/T43/1000 -> 9.2307692 | V43: 60 | W43: =V43*52 -> 3120 | X43: =V43*48*T43*0.8*0.81 -> 2426.112 | Y43: ✓
B44: Oficinas 2 | C44: Mini Split | D44: 12000 | E44: 1.3 | F44: =D44/E44/1000 -> 9.2307692 | G44: 60 | H44: =G44*52 -> 3120 | I44: =G44*48*E44*0.8*0.81 -> 2426.112 | Q44: Oficinas 2 | R44: Mini Split | S44: 12000 | T44: 1.3 | U44: =S44/T44/1000 -> 9.2307692 | V44: 60 | W44: =V44*52 -> 3120 | X44: =V44*48*T44*0.8*0.81 -> 2426.112 | Y44: ✓
B45: Oficinas 3 | C45: Mini Split | D45: 12000 | E45: 1.3 | F45: =D45/E45/1000 -> 9.2307692 | G45: 60 | H45: =G45*52 -> 3120 | I45: =G45*48*E45*0.8*0.81 -> 2426.112 | Q45: Oficinas 3 | R45: Mini Split | S45: 12000 | T45: 1.3 | U45: =S45/T45/1000 -> 9.2307692 | V45: 60 | W45: =V45*52 -> 3120 | X45: =V45*48*T45*0.8*0.81 -> 2426.112 | Y45: ✓
B46: Sala de reuniones | C46: Mini Split | D46: 12000 | E46: 1.3 | F46: =D46/E46/1000 -> 9.2307692 | G46: 60 | H46: =G46*52 -> 3120 | I46: =G46*48*E46*0.8*0.81 -> 2426.112 | Q46: Sala de reuniones | R46: Mini Split | S46: 12000 | T46: 1.3 | U46: =S46/T46/1000 -> 9.2307692 | V46: 60 | W46: =V46*52 -> 3120 | X46: =V46*48*T46*0.8*0.81 -> 2426.112 | Y46: ✓
B47: Total | E47: =SUM(E40:E46) -> 21.46 | G47: =SUM(G40:G46) -> 420 | H47: =SUM(H40:H46) -> 21840 | I47: =SUM(I40:I46) -> 40049.51 | Q47: Total | T47: =SUM(T40:T46) -> 21.46 | V47: =SUM(V40:V46) -> 420 | W47: =SUM(W40:W46) -> 21840 | X47: =SUM(X40:X46) -> 40049.51
M60: Ejemplo | AB60: Ejemplo
D61: Eficiencia energética = (Energía de salida útil / Energía de entrada) x 100% | J61: Factor de carga del equipo | M61: 0.8 | S61: Eficiencia energética = (Energía de salida útil / Energía de entrada) x 100% | Y61: Factor de carga del equipo | AB61: 0.8
D62: EER = 12,000 BTU/h / 1,200 W | J62: Factor de potencia del equipo | M62: 0.75 | S62: EER = 12,000 BTU/h / 1,200 W | Y62: Factor de potencia del equipo | AB62: 0.75
D63: EER = 10 | S63: EER = 10
...

Sheet Inventario
B3: Área | C3: Tipo | D3: Potencia [W] | E3: Cantidad | F3: Potencia instalada [W] | G3: Uso aproximado (h/día) | H3: Consumo anual [kWh/año]
B4: Oficina Lab de Control | C4: Tubo fluorescente | D4: 32 | E4: 24 | F4: =D4*E4 -> 768 | G4: 9 | H4: =F4*G4*313/1000 -> 2163.456
C5: Foco fluorescente | D5: 25 | E5: 1 | F5: =D5*E5 -> 25 | G5: 9 | H5: =F5*G5*313/1000 -> 70.425
B6: Exteriores | C6: Foco fluorescente | D6: 25 | E6: 2 | F6: =D6*E6 -> 50 | G6: 6 | H6: =F6*G6*313/1000 -> 93.9
C7: Perimetrales | D7: 75 | E7: 2 | F7: =D7*E7 -> 150 | G7: 12 | H7: =F7*G7*313/1000 -> 563.4
B8: Lab Suelos | C8: Tubo fluorescente | D8: 32 | E8: 30 | F8: =D8*E8 -> 960 | G8: 9 | H8: =F8*G8*313/1000 -> 2704.32
B9: Lab I+D | C9: Tubo fluorescente | D9: 32 | E9: 51 | F9: =D9*E9 -> 1632 | G9: 9 | H9: =F9*G9*313/1000 -> 4597.344
C10: Lámpara fluorescente | D10: 25 | E10: 1 | F10: =D10*E10 -> 25 | G10: 9 | H10: =F10*G10*313/1000 -> 70.425
B11: Oficinas 1 | C11: Tubo fluorescente | D11: 32 | E11: 8 | F11: =D11*E11 -> 256 | G11: 9 | H11: =F11*G11*313/1000 -> 721.152
B12: Oficinas 2 | C12: Tubo fluorescente | D12: 32 | E12: 12 | F12: =D12*E12 -> 384 | G12: 9 | H12: =F12*G12*313/1000 -> 1081.728
B13: Baños | C13: Tubo fluorescente | D13: 32 | E13: 2 | F13: =D13*E13 -> 64 | G13: 1 | H13: =F13*G13*313/1000 -> 20.032
B14: Oficinas 3 | C14: Tubo fluorescente | D14: 32 | E14: 3 | F14: =D14*E14 -> 96 | G14: 9 | H14: =F14*G14*313/1000 -> 270.432
B15: Pasillo | C15: Tubo fluorescente | D15: 32 | E15: 6 | F15: =D15*E15 -> 192 | G15: 9 | H15: =F15*G15*313/1000 -> 540.864
B16: Cocina | C16: Foco fluorescente | D16: 25 | E16: 2 | F16: =D16*E16 -> 50 | G16: 4 | H16: =F16*G16*313/1000 -> 62.6
B17: Sala de reuniones | C17: Tubo fluorescente | D17: 32 | E17: 12 | F17: =D17*E17 -> 384 | G17: 0.3 | H17: =F17*G17*313/1000 -> 36.0576
B18: Total | F18: =SUM(F4:F17) -> 5036 | H18: =SUM(H4:H17) -> 12996.136
J22: Área | K22: Tipo | L22: Capacidad [BTU/h] | M22: Potencia [kW] | N22: EER | O22: Horas Semana | P22: Horas año | Q22: Consumo anual [kWh/año]
J23: Lab. de Control | K23: Mini Split | L23: 12000 | M23: 1.26 | N23: =L23/M23/1000 -> 9.5238095 | O23: 60 | P23: =O23*52 -> 3120 | Q23: =O23*48*M23*0.8*0.81 -> 2351.4624
J24: Lab. de Control | K24: Central | L24: 60000 | M24: 7.5 | N24: =L24/M24/1000 -> 8 | O24: 60 | P24: =O24*52 -> 3120 | Q24: =O24*48*M24*0.8*0.81 -> 13996.8
J25: Lab. de Suelos | K25: Central | L25: 60000 | M25: 7.5 | N25: =L25/M25/1000 -> 8 | O25: 60 | P25: =O25*52 -> 3120 | Q25: =O25*48*M25*0.8*0.81 -> 13996.8
J26: Oficinas 1 | K26: Mini Split | L26: 12000 | M26: 1.3 | N26: =L26/M26/1000 -> 9.2307692 | O26: 60 | P26: =O26*52 -> 3120 | Q26: =O26*48*M26*0.8*0.81 -> 2426.112
J27: Oficinas 2 | K27: Mini Split | L27: 12000 | M27: 1.3 | N27: =L27/M27/1000 -> 9.2307692 | O27: 60 | P27: =O27*52 -> 3120 | Q27: =O27*48*M27*0.8*0.81 -> 2426.112
J28: Oficinas 3 | K28: Mini Split | L28: 12000 | M28: 1.3 | N28: =L28/M28/1000 -> 9.2307692 | O28: 60 | P28: =O28*52 -> 3120 | Q28: =O28*48*M28*0.8*0.81 -> 2426.112
J29: Sala de reuniones | K29: Mini Split | L29: 12000 | M29: 1.3 | N29: =L29/M29/1000 -> 9.2307692 | O29: 60 | P29: =O29*52 -> 3120 | Q29: =O29*48*M29*0.8*0.81 -> 2426.112
J30: Total | M30: =SUM(M23:M29) -> 21.46 | O30: =SUM(O23:O29) -> 420 | P30: =SUM(P23:P29) -> 21840 | Q30: =SUM(Q23:Q29) -> 40049.51
S32: Área | T32: Descripción | U32: Capacidad instalada [kW] | V32: Hora de uso diario | W32: Factor de carga | X32: [Kwh]/día | Y32: [Kwh]/mes | Z32: [Kwh]/año
S33: Agua jabonosa y aditivos | T33: Bomba de pozo | U33: 0.7 | V33: 4 | W33: 0.9 | X33: =U33*V33*W33 -> 2.52 | Y33: =X33*5 -> 12.6 | Z33: =Y33*12 -> 151.2
T34: Bomba mezclador | U34: 5.6 | V34: 4 | W34: 0.9 | X34: =U34*V34*W34 -> 20.16 | Y34: =X34*5 -> 100.8 | Z34: =Y34*12 -> 1209.6
T35: Bomba para ácido | U35: 1.5 | V35: 4 | W35: 0.9 | X35: =U35*V35*W35 -> 5.4 | Y35: =X35*5 -> 27 | Z35: =Y35*12 -> 324
T36: Bomba para jabón (estanque de preparación) | U36: 3 | V36: 4 | W36: 0.9 | X36: =U36*V36*W36 -> 10.8 | Y36: =X36*5 -> 54 | Z36: =Y36*12 -> 648
T37: Bomba de kereosene (calentar agua) | U37: 0.2 | V37: 4 | W37: 0.9 | X37: =U37*V37*W37 -> 0.72 | Y37: =X37*5 -> 3.6 | Z37: =Y37*12 -> 43.2
T38: Bomba de jabón (agua preparada) | U38: 2.2 | V38: 4 | W38: 0.9 | X38: =U38*V38*W38 -> 7.92 | Y38: =X38*5 -> 39.6 | Z38: =Y38*12 -> 475.2
T39: Motor rotador emulsión | U39: 8.2 | V39: 4 | W39: 0.9 | X39: =U39*V39*W39 -> 29.52 | Y39: =X39*5 -> 147.6 | Z39: =Y39*12 -> 1771.2
S40: Emulsión | T40: Bomba de asfalto ex | U40: 3.7 | V40: 4 | W40: 0.9 | X40: =U40*V40*W40 -> 13.32 | Y40: =X40*5 -> 66.6 | Z40: =Y40*12 -> 799.2
T41: Bomba de asfalto in | U41: 11.2 | V41: 4 | W41: 0.9 | X41: =U41*V41*W41 -> 40.32 | Y41: =X41*5 -> 201.6 | Z41: =Y41*12 -> 2419.2
T42: Motor aceite térmico | U42: 1.3 | V42: 4 | W42: 0.9 | X42: =U42*V42*W42 -> 4.68 | Y42: =X42*5 -> 23.4 | Z42: =Y42*12 -> 280.8
S43: Almacenamiento | T43: Bomba de emulsión | U43: 5.6 | V43: 4 | W43: 0.9 | X43: =U43*V43*W43 -> 20.16 | Y43: =X43*5 -> 100.8 | Z43: =Y43*12 -> 1209.6
S44: Nodriza | T44: Motor de mezcladora | U44: 22.4 | V44: 4 | W44: 0.9 | X44: =U44*V44*W44 -> 80.64 | Y44: =X44*5 -> 403.2 | Z44: =Y44*12 -> 4838.4
T45: Bomba de emulsiones | U45: 7.5 | V45: 4 | W45: 0.9 | X45: =U45*V45*W45 -> 27 | Y45: =X45*5 -> 135 | Z45: =Y45*12 -> 1620
T46: Motor de reductores 3/8 | U46: 1.5 | V46: 4 | W46: 0.9 | X46: =U46*V46*W46 -> 5.4 | Y46: =X46*5 -> 27 | Z46: =Y46*12 -> 324
...

Sheet Pareto
C1: Inventario de motores de la empresa
B3: Área | C3: Descripción | D3: Capacidad instalada [kW] | E3: Hora de uso diario | F3: Factor de carga | G3: [Kwh]/día | H3: [Kwh]/mes | I3: [Kwh]/año | L3: [Kwh]/año | Y3: Diseño en .vsd, by PGF
B4: Agua jabonosa y aditivos | C4: Bomba de pozo | D4: 0.7 | E4: 4 | F4: 0.9 | G4: =D4*E4*F4 -> 2.52 | H4: =G4*5 -> 12.6 | I4: =H4*12 -> 151.2 | J4: ✓ | K4: Proceso 02 | L4: =SUM(I4:I14) -> 9331.2
C5: Bomba mezclador | D5: 5.6 | E5: 4 | F5: 0.9 | G5: =D5*E5*F5 -> 20.16 | H5: =G5*5 -> 100.8 | I5: =H5*12 -> 1209.6 | J5: ✓
C6: Bomba para ácido | D6: 1.5 | E6: 4 | F6: 0.9 | G6: =D6*E6*F6 -> 5.4 | H6: =G6*5 -> 27 | I6: =H6*12 -> 324 | J6: ✓
C7: Bomba para jabón (estanque de preparación) | D7: 3 | E7: 4 | F7: 0.9 | G7: =D7*E7*F7 -> 10.8 | H7: =G7*5 -> 54 | I7: =H7*12 -> 648 | J7: ✓
C8: Bomba de kereosene (calentar agua) | D8: 0.2 | E8: 4 | F8: 0.9 | G8: =D8*E8*F8 -> 0.72 | H8: =G8*5 -> 3.6 | I8: =H8*12 -> 43.2 | J8: ✓
C9: Bomba de jabón (agua preparada) | D9: 2.2 | E9: 4 | F9: 0.9 | G9: =D9*E9*F9 -> 7.92 | H9: =G9*5 -> 39.6 | I9: =H9*12 -> 475.2 | J9: ✓
C10: Motor rotador emulsión | D10: 8.2 | E10: 4 | F10: 0.9 | G10: =D10*E10*F10 -> 29.52 | H10: =G10*5 -> 147.6 | I10: =H10*12 -> 1771.2 | J10: ✓
B11: Emulsión | C11: Bomba de asfalto ex | D11: 3.7 | E11: 4 | F11: 0.9 | G11: =D11*E11*F11 -> 13.32 | H11: =G11*5 -> 66.6 | I11: =H11*12 -> 799.2 | J11: ✓
C12: Bomba de asfalto in | D12: 11.2 | E12: 4 | F12: 0.9 | G12: =D12*E12*F12 -> 40.32 | H12: =G12*5 -> 201.6 | I12: =H12*12 -> 2419.2 | J12: ✓
C13: Motor aceite térmico | D13: 1.3 | E13: 4 | F13: 0.9 | G13: =D13*E13*F13 -> 4.68 | H13: =G13*5 -> 23.4 | I13: =H13*12 -> 280.8 | J13: ✓
B14: Almacenamiento | C14: Bomba de emulsión | D14: 5.6 | E14: 4 | F14: 0.9 | G14: =D14*E14*F14 -> 20.16 | H14: =G14*5 -> 100.8 | I14: =H14*12 -> 1209.6 | J14: ✓
B15: Nodriza | C15: Motor de mezcladora | D15: 22.4 | E15: 4 | F15: 0.9 | G15: =D15*E15*F15 -> 80.64 | H15: =G15*5 -> 403.2 | I15: =H15*12 -> 4838.4 | J15: ✓ | K15: Proceso 03 | L15: =SUM(I15:I23) -> 8899.2
C16: Bomba de emulsiones | D16: 7.5 | E16: 4 | F16: 0.9 | G16: =D16*E16*F16 -> 27 | H16: =G16*5 -> 135 | I16: =H16*12 -> 1620 | J16: ✓
C17: Motor de reductores 3/8 | D17: 1.5 | E17: 4 | F17: 0.9 | G17: =D17*E17*F17 -> 5.4 | H17: =G17*5 -> 27 | I17: =H17*12 -> 324 | J17: ✓
C18: Motor de reductores 3/4 | D18: 1.5 | E18: 4 | F18: 0.9 | G18: =D18*E18*F18 -> 5.4 | H18: =G18*5 -> 27 | I18: =H18*12 -> 324 | J18: ✓
C19: Motor reductor de chispa | D19: 1.5 | E19: 4 | F19: 0.9 | G19: =D19*E19*F19 -> 5.4 | H19: =G19*5 -> 27 | I19: =H19*12 -> 324 | J19: ✓
C20: Motor banda transportadora | D20: 1.6 | E20: 4 | F20: 0.9 | G20: =D20*E20*F20 -> 5.76 | H20: =G20*5 -> 28.8 | I20: =H20*12 -> 345.6 | J20: ✓
C21: Bomba de agua | D21: 1.5 | E21: 4 | F21: 0.9 | G21: =D21*E21*F21 -> 5.4 | H21: =G21*5 -> 27 | I21: =H21*12 -> 324 | J21: ✓
C22: Bomba de asfalto | D22: 0.7 | E22: 4 | F22: 0.9 | G22: =D22*E22*F22 -> 2.52 | H22: =G22*5 -> 12.6 | I22: =H22*12 -> 151.2 | J22: ✓
C23: Bomba contra incendio | D23: 3 | E23: 4 | F23: 0.9 | G23: =D23*E23*F23 -> 10.8 | H23: =G23*5 -> 54 | I23: =H23*12 -> 648 | J23: ✓
C24: Total | D24: =SUM(D4:D23) -> 84.4 | G24: =SUM(G4:G23) -> 303.84 | H24: =SUM(H4:H23) -> 1519.2 | I24: =SUM(I4:I23) -> 18230.4
H26: 1519.2 | I26: 18230.4
C39: Datos de consumo eléctrico de molino coloidal
S40: [Kwh]/año | W40: [Kwh]/año
B41: Área | C41: Descripción | D41: Capacidad instalada [kW] | E41: Hora de uso diario | F41: Factor de carga | G41: [KWh]/día | H41: [KWh]/mes | I41: [KWh]/año | L41: [Kwh]/año | Q41: Eléctrico | S41: =L4+L15+L42+L48+L51+L80+L87+L115 -> 104946.4 | V41: Combustible | W41: =N131+N133+N137 -> 134455.55
B42: Emulsión | C42: Molino coloidal | D42: 37.29 | E42: 4 | F42: 0.9 | G42: =D42*E42*F42 -> 134.244 | H42: =G42*5 -> 671.22 | I42: =H42*12 -> 8054.64 | J42: ✓ | K42: Proceso 02 | L42: =I42 -> 8054.64
Q43: Factura E | S43: ='Consumo Eléctrico'!I33 -> 114268.13 | V43: Factura C | W43: ='Consumo Térmico de la empresa'!S39 -> 134458.09
H44: 671.22 | I44: 8054.64
C45: Inventario de aires acondicionados de la empresa | Q45: Otros | S45: =S43-S41 -> 9321.734 | V45: Delta | W45: =W43-W41 -> 2.5383688
S46: =S45/12 -> 776.81117
B47: Área | C47: Tipo | D47: Capacidad [BTU/h] | E47: Potencia [kW] | F47: EER | G47: Horas Semana | H47: Horas año | I47: Consumo anual [kWh/año] | L47: [Kwh]/año
B48: Lab. de Control | C48: Mini Split | D48: 12000 | E48: 1.26 | F48: =D48/E48/1000 -> 9.5238095 | G48: 60 | H48: =G48*52 -> 3120 | I48: =G48*48*E48*0.8*0.81 -> 2351.4624 | J48: ✓ | K48: Sector 02 | L48: =SUM(I48:I50) -> 30345.062 | Q48: Consumo Energético Total
B49: Lab. de Control | C49: Central | D49: 60000 | E49: 7.5 | F49: =D49/E49/1000 -> 8 | G49: 60 | H49: =G49*52 -> 3120 | I49: =G49*48*E49*0.8*0.81 -> 13996.8 | J49: ✓ | Q49: [Kwh]/año | Z49: [Kwh]/año
B50: Lab. de Suelos | C50: Central | D50: 60000 | E50: 7.5 | F50: =D50/E50/1000 -> 8 | G50: 60 | H50: =G50*52 -> 3120 | I50: =G50*48*E50*0.8*0.81 -> 13996.8 | J50: ✓ | Q50: Electricidad | S50: Kerosene | U50: % | V50: % acum | Z50: Electricidad | AA50: Kerosene | AB50: % | AC50: % acum | AO50: USE´s | AP50: Electricidad GEI | AQ50: Kerosene GEI | AR50: % | AS50: % acum | BE50: =AO50 -> USE´s | BF50: Emisiones GEI | BG50: =AR50 -> % | BH50: =AS50 -> % acum
B51: Oficinas 1 | C51: Mini Split | D51: 12000 | E51: 1.3 | F51: =D51/E51/1000 -> 9.2307692 | G51: 60 | H51: =G51*52 -> 3120 | I51: =G51*48*E51*0.8*0.81 -> 2426.112 | J51: ✓ | K51: Sector 01 | L51: =SUM(I51:I54) -> 9704.448 | P51: Proceso 01 | S51: =N133 -> 49399.746 | U51: =(Q51+S51)/($Q$58+$S$58) -> 0.19861296 | V51: =U51 -> 0.19861296 | Y51: =P52 -> Proceso 02 | Z51: =Q52 -> 17385.84 | AA51: =S52 -> 85055.802 | AB51: =(Z51+AA51)/($Z$58+$AA$58) -> 0.41186928 | AC51: =AB51 -> 0.41186928 | AO51: =Y51 -> Proceso 02 | AP51: =Z51*'Emisiones de GEI'!$D$52/1000 -> 4.1447843 | AQ51: =AA51*'Emisiones de GEI'!$G$53/1000 -> 22.015844 | AR51: =(AP51+AQ51)/($AP$58+$AQ$58) -> 0.42164641 | AS51: =AR51 -> 0.42164641 | BE51: =AO51 -> Proceso 02 | BF51: =AP51+AQ51 -> 26.160628 | BG51: =BF51/$BF$58 -> 0.42164641 | BH51: =BG51 -> 0.42164641
B52: Oficinas 2 | C52: Mini Split | D52: 12000 | E52: 1.3 | F52: =D52/E52/1000 -> 9.2307692 | G52: 60 | H52: =G52*52 -> 3120 | I52: =G52*48*E52*0.8*0.81 -> 2426.112 | J52: ✓ | P52: Proceso 02 | Q52: =L4+L42 -> 17385.84 | S52: =N131+N137 -> 85055.802 | U52: =(Q52+S52)/($Q$58+$S$58) -> 0.41186928 | V52: =V51+U52 -> 0.61048224 | Y52: =P55 -> Sector 02 | Z52: =Q55 -> 66224.042 | AA52: =S55 -> 0 | AB52: =(Z52+AA52)/($Z$58+$AA$58) -> 0.26625548 | AC52: =AC51+AB52 -> 0.67812476 | AO52: =Y52 -> Sector 02 | AP52: =Z52*'Emisiones de GEI'!$D$52/1000 -> 15.787812 | AQ52: =AA52*'Emisiones de GEI'!$G$53/1000 -> 0 | AR52: =(AP52+AQ52)/($AP$58+$AQ$58) -> 0.25446155 | AS52: =AS51+AR52 -> 0.67610796 | BE52: =AO52 -> Sector 02 | BF52: =AP52+AQ52 -> 15.787812 | BG52: =BF52/$BF$58 -> 0.25446155 | BH52: =BH51+BG52 -> 0.67610796
B53: Oficinas 3 | C53: Mini Split | D53: 12000 | E53: 1.3 | F53: =D53/E53/1000 -> 9.2307692 | G53: 60 | H53: =G53*52 -> 3120 | I53: =G53*48*E53*0.8*0.81 -> 2426.112 | J53: ✓ | P53: Proceso 03 | Q53: =L15 -> 8899.2 | U53: =(Q53+S53)/($Q$58+$S$58) -> 0.035779464 | V53: =V52+U53 -> 0.6462617 | Y53: =P51 -> Proceso 01 | Z53: =Q51 -> 0 | AA53: =S51 -> 49399.746 | AB53: =(Z53+AA53)/($Z$58+$AA$58) -> 0.19861296 | AC53: =AC52+AB53 -> 0.87673772 | AO53: =Y53 -> Proceso 01 | AP53: =Z53*'Emisiones de GEI'!$D$52/1000 -> 0 | AQ53: =AA53*'Emisiones de GEI'!$G$53/1000 -> 12.78663 | AR53: =(AP53+AQ53)/($AP$58+$AQ$58) -> 0.20608973 | AS53: =AS52+AR53 -> 0.88219769 | BE53: =AO53 -> Proceso 01 | BF53: =AP53+AQ53 -> 12.78663 | BG53: =BF53/$BF$58 -> 0.20608973 | BH53: =BH52+BG53 -> 0.88219769
B54: Sala de reuniones | C54: Mini Split | D54: 12000 | E54: 1.3 | F54: =D54/E54/1000 -> 9.2307692 | G54: 60 | H54: =G54*52 -> 3120 | I54: =G54*48*E54*0.8*0.81 -> 2426.112 | J54: ✓ | P54: Sector 01 | Q54: =L51+L87 -> 12437.314 | U54: =(Q54+S54)/($Q$58+$S$58) -> 0.050004542 | V54: =V53+U54 -> 0.69626625 | Y54: =P54 -> Sector 01 | Z54: =Q54 -> 12437.314 | AA54: =S54 -> 0 | AB54: =(Z54+AA54)/($Z$58+$AA$58) -> 0.050004542 | AC54: =AC53+AB54 -> 0.92674226 | AO54: =Y54 -> Sector 01 | AP54: =Z54*'Emisiones de GEI'!$D$52/1000 -> 2.9650556 | AQ54: =AA54*'Emisiones de GEI'!$G$53/1000 -> 0 | AR54: =(AP54+AQ54)/($AP$58+$AQ$58) -> 0.047789565 | AS54: =AS53+AR54 -> 0.92998725 | BE54: =AO54 -> Sector 01 | BF54: =AP54+AQ54 -> 2.9650556 | BG54: =BF54/$BF$58 -> 0.047789565 | BH54: =BH53+BG54 -> 0.92998725
...

Sheet Balance Energético
B4: USE´s | C4: Nomenclatura USE´s | D4: Electricidad | E4: Combustible | I4: =C5 -> Proc-01 (Quem) | J4: =C6 -> Proc-02 (Mot A J) | K4: =C7 -> Proc-02 (Mot E) | L4: =C8 -> Proc-02 (BB Alm) | M4: =C9 -> Proc-03 (BBs y Mots Nod) | N4: =C10 -> Sect_01 (AA Of) | O4: =C11 -> Sect_01 (Lum Of) | P4: =C12 -> Sect_02 (AA Of) | Q4: =C13 -> Sect_02 (Lum Of) | R4: =C14 -> Sect_02 (Eq Lab) | S4: =C15 -> Varios
B5: Proc-01 Quemadores | C5: Proc-01 (Quem) | D5: =Pareto!R65 -> 0 | E5: =Pareto!T65 -> 0.36740578 | F5: =(D5+E5)/2 -> 0.18370289 | H5: Electricidad | I5: =D5 -> 0 | J5: =D6 -> 0.040452224 | K5: =D7 -> 0.10111166 | L5: =D8 -> 0.010585629 | M5: =D9 -> 0.077879983 | N5: =D10 -> 0.084926987 | O5: =D11 -> 0.023916254 | P5: =D12 -> 0.26556016 | Q5: =D13 -> 0.089817432 | R5: =D14 -> 0.22417195 | S5: =D15 -> 0.081577724 | T5: =SUM(I5:S5) -> 1
